Workbook

Sheet Sin foto
A1: SKU | B1: SKU inventario | C1: Producto | D1: Marca | E1: Categoría | F1: Precio | G1: Stock | H1: Estado inventario | I1: Tiene descripción | J1: Enlace del producto
A2: MOU-0183 | B2: MOU-0183 | C2: MOUSE ACER AMR100 AZUL | D2: Acer | E2: Mouses | F2: 39900 | G2: 24 | H2: vinculado | I2: NO | J2: https://allforall.com.co/producto/mouse-acer-amr100-azul
A3: MOU-0508 | B3: MOU-0508 | C3: MOUSE PREDATOR ACER PMW910 CESTUS 310 USB 6 BOTONES | D3: Acer | E3: Mouses | F3: 61900 | G3: 12 | H3: vinculado | I3: NO | J3: https://allforall.com.co/producto/mouse-predator-acer-pmw910-cestus-310-usb-6-botones-mou-0508
A4: MEM-0440 | B4: MEM-0440 | C4: MEMORIA USB ADATA 128 GB UR350-128GRSR/BK | D4: ADATA | E4: Memorias | F4: 61900 | G4: 18 | H4: vinculado | I4: NO | J4: https://allforall.com.co/producto/memoria-usb-adata-128-gb-ur350-128grsr-bk
A5: SSD-0438 | B5: SSD-0438 | C5: SSD EXTERNO ADATA 1 TB SC735-1000GCCBK/BU | D5: ADATA | E5: Discos | F5: 656900 | G5: 1 | H5: vinculado | I5: NO | J5: https://allforall.com.co/producto/ssd-externo-adata-1-tb-sc735-1000gccbk-bu
A6: MON-0819 | B6: SSD-0437 | C6: SSD EXTERNO ADATA 1TB SD620 - 1TCBK | D6: ADATA | E6: Discos | F6: 513900 | G6: 1 | H6: vinculado | I6: NO | J6: https://allforall.com.co/producto/ssd-externo-adata-1tb-sc610-1000gcbk-rd
A7: SSD-0439 | B7: SSD-0439 | C7: SSD EXTERNO ADATA 2 TB SC735-2000GCCBK/BU | D7: ADATA | E7: Discos | F7: 1093900 | G7: 1 | H7: vinculado | I7: NO | J7: https://allforall.com.co/producto/ssd-externo-adata-2-tb-sc735-2000gccbk-bu
A8: CUB-0308 | B8: CUB-0308 | C8: BASCULA CUBITT SAMART SCALE CT- COLOR NEGRA | D8: Cubitt | E8: Hogar / Cocina | F8: 87900 | G8: 1 | H8: vinculado | I8: NO | J8: https://allforall.com.co/producto/cubitt-samart-scale-ct-color-negra
A9: IMP-0473 | B9: IMP-0473 | C9: IMPRESORA TERMICA TM-T20IIICONEXION USB+SERIAL | D9: Epson | E9: Impresoras | F9: 408900 | G9: 2 | H9: vinculado | I9: NO | J9: https://allforall.com.co/producto/impresora-termica-tm-t20iiiconexion-usb-serial
A10: CAM-0525 | B10: CAM-0525 | C10: CAMARA EUFY INDOOR E30 | D10: Eufy | E10: Hogar inteligente | F10: 195900 | G10: 2 | H10: vinculado | I10: NO | J10: https://allforall.com.co/producto/camara-eufy-indoor-e30-cam-0525
A11: CAM-0524 | B11: CAM-0524 | C11: CAMARA EUFY SOLOCAM C210 | D11: Eufy | E11: Hogar inteligente | F11: 160900 | G11: 2 | H11: vinculado | I11: NO | J11: https://allforall.com.co/producto/camara-eufy-solocam-c210-cam-0524
A12: CAM-0494 | B12: CAM-0494 | C12: CAMARA EUFY SOLOCAM E30 | D12: Eufy | E12: Hogar inteligente | F12: 396900 | G12: 2 | H12: vinculado | I12: NO | J12: https://allforall.com.co/producto/camara-eufy-solocam-e30-cam-0494
A13: CRU-0318 | B13: CRU-0318 | C13: CRUCETA FERRENOVO PLEGABLE FN-23213 | D13: Ferrenovo | E13: Artículos para Auto | F13: 27900 | G13: 14 | H13: vinculado | I13: NO | J13: https://allforall.com.co/producto/cruceta-ferrenovo-plegable-fn-23213
... A15: LEC-0449 | B15: LEC-0449 | C15: LECTOR CODIGO DE BARRAS HONEYWELL LASER ORBIT MK7120 USB COLOR NEGRO 5V | D15: Honeywell | E15: Artículos y Electrónica | F15: 488900 | G15: 62 | H15: vinculado | I15: NO | J15: https://allforall.com.co/producto/lector-codigo-de-barras-honeywell-laser-orbit-mk7120-usb-color-negro-5v
A16: HP -0242 | C16: HP ENGAGE ONE PRIME WHITE | D16: HP | E16: Computadores | F16: 1769900 | G16: 0 | H16: sin_inventario | I16: NO | J16: https://allforall.com.co/producto/hp-engage-one-prime-white-2
A17: POR-0576 | B17: POR-0576 | C17: PORTATIL HP 14-EM0217LA ATHLON SILVER 7120U 8GB DDR5 512GB SSD | D17: HP | E17: Computadores | F17: 1394900 | G17: 1 | H17: vinculado | I17: NO | J17: https://allforall.com.co/producto/portatil-hp-14-em0217la-athlon-silver-7120u-8gb-ddr5-512gb-ssd
A18: POR-0436 | B18: POR-0436 | C18: PORTATIL HP 15-FD0332LA CORE 100U RAM 8GB DDR5 SSD 512 GB 15.6" PLATA | D18: HP | E18: PCs y Laptops | F18: 1798900 | G18: 1 | H18: vinculado | I18: NO | J18: https://allforall.com.co/producto/portatil-hp-15-fd0332la-core-100u-ram-8gb-ddr5-ssd-512-gb-15-6-plata
A19: DIA-0280 | B19: DIA-0280 | C19: DIADEMA JBL TUNE - 720BT - HEADPHONES BLANCO | D19: JBL | E19: Audífonos y Diademas | F19: 180900 | G19: 3 | H19: vinculado | I19: NO | J19: https://allforall.com.co/producto/diadema-jbl-tune-720bt-headphones-blanco
A20: DIS-0260 | B20: DIS-0260 | C20: DISCO SOLIDO SSD KINGSTON SNV3S/1000G 1TB NV3 | D20: Kingston | E20: Memorias | F20: 649900 | G20: 210 | H20: vinculado | I20: NO | J20: https://allforall.com.co/producto/disco-solido-ssd-kingston-snv3s-1000g-1tb-nv3
A21: PUN-0505 | B21: PUN-0505 | C21: PUNTERO LASER KPS-006 KLIP XTREME | D21: Klip Xtreme | E21: Accesorios | F21: 39900 | G21: 160 | H21: vinculado | I21: NO | J21: https://allforall.com.co/producto/puntero-laser-kps-006-klip-xtreme-pun-0505
A22: MOU-0160 | B22: MOU-0160 | C22: MOUSE LENOVO USB ALAMBRICO ESSENTIAL 4Y50R20863 | D22: Lenovo | E22: Mouses | F22: 26900 | G22: 8 | H22: vinculado | I22: NO | J22: https://allforall.com.co/producto/mouse-lenovo-usb-alambrico-essential-4y50r20863
A23: MEM-0214 | B23: MEM-0214 | C23: MEMORIA SD 128 GB SILVER PLUS LEXAR-13413 | D23: Lexar | E23: Memorias | F23: 235900 | G23: 3 | H23: vinculado | I23: NO | J23: https://allforall.com.co/producto/memoria-sd-128-gb-silver-plus-lexar-13413
A24: COM-0323 | B24: COM-0323 | C24: COMBO TECLADO Y MOUSE LOGITECH POP ICON ROSADO | D24: Logitech | E24: Combos Teclado y Mouse | F24: 186900 | G24: 1 | H24: vinculado | I24: NO | J24: https://allforall.com.co/producto/combo-teclado-y-mouse-logitech-pop-icon-rosado
A25: DIA-0481 | B25: DIA-0481 | C25: DIADEMA LOGITECH H151 STEREO | D25: Logitech | E25: Audífonos y Diademas | F25: 82900 | G25: 18 | H25: vinculado | I25: NO | J25: https://allforall.com.co/producto/diadema-logitech-h151-stereo
A26: DIA-0271 | B26: DIA-0271 | C26: DIADEMA LOGITECH H390 STEREO USB NEGRA | D26: Logitech | E26: Audífonos y Diademas | F26: 85900 | G26: 13 | H26: vinculado | I26: NO | J26: https://allforall.com.co/producto/diadema-logitech-h390-stereo-usb-negra
A27: DIA-0270 | B27: DIA-0270 | C27: DIADEMA LOGITECH ZONE 300 BLANCO | D27: Logitech | E27: Audífonos y Diademas | F27: 253900 | G27: 4 | H27: vinculado | I27: NO | J27: https://allforall.com.co/producto/diadema-logitech-zone-300-blanco
A28: DIA-0269 | B28: DIA-0269 | C28: DIADEMA LOGITECH ZONE 300 NEGRO GRAFITO | D28: Logitech | E28: Audífonos y Diademas | F28: 253900 | G28: 6 | H28: vinculado | I28: NO | J28: https://allforall.com.co/producto/diadema-logitech-zone-300-negro-grafito
... A57: CAB-0366 | B57: CAB-0366 | C57: CABLES DE PODER PARA PC | D57: Sin marca | E57: Cables | F57: 5900 | G57: 3 | H57: vinculado | I57: NO | J57: https://allforall.com.co/producto/cables-de-poder-para-pc
A58: CÁM-0360 | C58: CÁMARA INTELIGENTE LUNAR VTA+ MOVIMIENTO INTERIOR VTA-84848 | D58: Sin marca | E58: Cámaras de Seguridad | F58: 120900 | G58: 0 | H58: sin_inventario | I58: NO | J58: https://allforall.com.co/producto/camara-inteligente-lunar-vta-movimiento-interior-vta-84848-2
A59: CÁM-0359 | B59: CÁM-0359 | C59: CÁMARA INTELIGENTE OVO 2 VTA+ MOVIMIENTO 2K VTA-84709 | D59: Sin marca | E59: Cámaras de Seguridad | F59: 96900 | G59: 0 | H59: sin_inventario | I59: NO | J59: https://allforall.com.co/producto/camara-inteligente-ovo-2-vta-movimiento-2k-vta-84709
A60: CÁM-0358 | B60: CÁM-0358 | C60: CÁMARA INTELIGENTE PLUTO VTA+ 3K EXTERIOR WATERPROOF CON VISIÓN NOCTURNA A COLOR-84837 | D60: Sin marca | E60: Cámaras de Seguridad | F60: 91900 | G60: 0 | H60: sin_inventario | I60: NO | J60: https://allforall.com.co/producto/camara-inteligente-pluto-vta-3k-exterior-waterproof-con-vision-nocturna-a-color
A61: CÁM-0357 | B61: CÁM-0357 | C61: CÁMARA INTELIGENTE PRIMUS 2 VTA+ 3K MOVIMIENTO INTERIOR CON SIRENA Y VISIÓN NOCTURNA-84828 | D61: Sin marca | E61: Cámaras de Seguridad | F61: 116900 | G61: 0 | H61: sin_inventario | I61: NO | J61: https://allforall.com.co/producto/camara-inteligente-primus-2-vta-3k-movimiento-interior-con-sirena-y-vision-noctu
A62: CAM-0354 | B62: CAM-0354 | C62: CAMARA QHALI SMART Q CAM PRO BIDIRE 2 BLANCO | D62: Sin marca | E62: Cámaras de Seguridad | F62: 163900 | G62: 2 | H62: vinculado | I62: NO | J62: https://allforall.com.co/producto/camara-qhali-smart-q-cam-pro-bidire-2-blanco
A63: CAM-0353 | B63: CAM-0353 | C63: CAMARA VTA INTELIGENTE CON MOVIMIENTO EXTERIOR POKY 2K VTA-84955 | D63: Sin marca | E63: Cámaras de Seguridad | F63: 118900 | G63: 2 | H63: vinculado | I63: NO | J63: https://allforall.com.co/producto/camara-vta-inteligente-con-movimiento-exterior-poky-2k-vta-8-cam-0353
A64: CAM-0355 | B64: CAM-0355 | C64: CAMARA WEB KISONLI 480p BLANCA | D64: Sin marca | E64: Cámaras de Seguridad | F64: 34900 | G64: 3 | H64: vinculado | I64: SI | J64: https://allforall.com.co/producto/camara-kisonli-blanca
A65: CAM-0469 | B65: CAM-0469 | C65: CAMARA WEB LOGITECH C922 PRO STREAM NEGRO | D65: Sin marca | E65: Cámaras de Seguridad | F65: 346900 | G65: 3 | H65: vinculado | I65: NO | J65: https://allforall.com.co/producto/camara-web-logitech-c922-pro-stream-negro
A66: CAM-0350 | B66: CAM-0350 | C66: CAMARA WEB TRUST SPOTLIGHT PRO | D66: Sin marca | E66: Accesorios para PC | F66: 69900 | G66: 1 | H66: vinculado | I66: NO | J66: https://allforall.com.co/producto/camara-web-trust-spotlight-pro-cam-0350
A67: CAM-0519 | B67: CAM-0519 | C67: CAMARA WEB TRUST SPOTLIGHT PRO | D67: Sin marca | E67: Cámaras de Seguridad | F67: 69900 | G67: 1 | H67: vinculado | I67: NO | J67: https://allforall.com.co/producto/camara-web-trust-spotlight-pro-cam-0519
A68: CAR-0349 | B68: CAR-0349 | C68: CARGADOR 35 W 1 USN Y 1 USB C NEGRO MAS CABLE DE 1,5 METROS | D68: Sin marca | E68: Cargadores | F68: 47900 | G68: 1 | H68: vinculado | I68: NO | J68: https://allforall.com.co/producto/cargador-35-w-1-usn-y-1-usb-c-negro-mas-cable-de-1-5-metros
A69: CAR-0348 | B69: CAR-0348 | C69: CARGADOR APPLE 20W ORIGINAL USB-C | D69: Sin marca | E69: Cargadores | F69: 66900 | G69: 23 | H69: vinculado | I69: NO | J69: https://allforall.com.co/producto/cargador-apple-20w-original-usb-c
...

Sheet Resumen
A1: 274 de 850 productos activos no tienen ninguna imagen — datos del 15/09/2026
A2: Fuente: base de datos de la tienda All For All (tabla products, productos sin imágenes). Conteos calculados con COUNTIF sobre la hoja 'Sin foto'.
A4: Productos sin foto por marca (mayor a menor)
A5: Marca | B5: Productos sin foto
A6: Sin marca | B6: =COUNTIF('Sin foto'!$D$2:$D$275,A6) -> 232
A7: Logitech | B7: =COUNTIF('Sin foto'!$D$2:$D$275,A7) -> 12
A8: ADATA | B8: =COUNTIF('Sin foto'!$D$2:$D$275,A8) -> 4
A9: Eufy | B9: =COUNTIF('Sin foto'!$D$2:$D$275,A9) -> 3
A10: HP | B10: =COUNTIF('Sin foto'!$D$2:$D$275,A10) -> 3
A11: Tezzio | B11: =COUNTIF('Sin foto'!$D$2:$D$275,A11) -> 3
A12: Acer | B12: =COUNTIF('Sin foto'!$D$2:$D$275,A12) -> 2
A13: Cubitt | B13: =COUNTIF('Sin foto'!$D$2:$D$275,A13) -> 1
A14: Epson | B14: =COUNTIF('Sin foto'!$D$2:$D$275,A14) -> 1
A15: Ferrenovo | B15: =COUNTIF('Sin foto'!$D$2:$D$275,A15) -> 1
A16: Forza | B16: =COUNTIF('Sin foto'!$D$2:$D$275,A16) -> 1
A17: Honeywell | B17: =COUNTIF('Sin foto'!$D$2:$D$275,A17) -> 1
... A27: Trust | B27: =COUNTIF('Sin foto'!$D$2:$D$275,A27) -> 1
A28: Total | B28: =SUM(B6:B27) -> 274
A31: Productos sin foto por categoría (mayor a menor)
A32: Categoría | B32: Productos sin foto
A33: Mouses | B33: =COUNTIF('Sin foto'!$E$2:$E$275,A33) -> 46
A34: Audífonos y Diademas | B34: =COUNTIF('Sin foto'!$E$2:$E$275,A34) -> 41
A35: Memorias | B35: =COUNTIF('Sin foto'!$E$2:$E$275,A35) -> 25
A36: Pad Mouse | B36: =COUNTIF('Sin foto'!$E$2:$E$275,A36) -> 12
A37: Teclados | B37: =COUNTIF('Sin foto'!$E$2:$E$275,A37) -> 12
A38: Cables | B38: =COUNTIF('Sin foto'!$E$2:$E$275,A38) -> 12
A39: Morrales y Bolsos | B39: =COUNTIF('Sin foto'!$E$2:$E$275,A39) -> 10
A40: Termos | B40: =COUNTIF('Sin foto'!$E$2:$E$275,A40) -> 10
A41: Cámaras de Seguridad | B41: =COUNTIF('Sin foto'!$E$2:$E$275,A41) -> 9
A42: Artículos y Electrónica | B42: =COUNTIF('Sin foto'!$E$2:$E$275,A42) -> 7
A43: PCs y Laptops | B43: =COUNTIF('Sin foto'!$E$2:$E$275,A43) -> 7
A44: Accesorios para PC | B44: =COUNTIF('Sin foto'!$E$2:$E$275,A44) -> 6
... A69: Televisores | B69: =COUNTIF('Sin foto'!$E$2:$E$275,A69) -> 1
A70: Total | B70: =SUM(B33:B69) -> 274
